Workbook
Name K_LevyCap: Assumptions!$C$7
Name K_ResTrail: Assumptions!$C$8
Name K_ComTrail: Assumptions!$C$9
Name K_TrendRate: Assumptions!$C$10
Name K_ResNewShare: Assumptions!$C$11
Name K_ComNewShare: Assumptions!$C$12
Name K_PP: Assumptions!$C$13
Name K_ResNewPct: Assumptions!$C$14
Name K_ResRenoPct: Assumptions!$C$15
Name K_ComNewPct: Assumptions!$C$16
Name K_ComRenoPct: Assumptions!$C$17
Name K_TownNG: Assumptions!$C$18
Name K_Perm27: Assumptions!$C$19
Name K_Perm27Lo: Assumptions!$C$20
Name K_Perm27Hi: Assumptions!$C$21
Name K_Perm28: Assumptions!$C$22
Name K_Perm28Lo: Assumptions!$C$23
Name K_Perm28Hi: Assumptions!$C$24
Name K_NG2026: Assumptions!$C$25
Name Levy2025: Assumptions!$C$26
Name K_HomesPace: Assumptions!$C$29
Name K_ResValUnit: Assumptions!$C$30
Name K_ResApp: Assumptions!$C$31
Name K_ComValSqft: Assumptions!$C$32
Name K_ComApp: Assumptions!$C$33
Name K_ResTax: Assumptions!$C$34
Name K_ComTax: Assumptions!$C$35
Name K_ResValShare: Assumptions!$C$36
Name K_LevyGrowth: Assumptions!$C$37
Name K_BlendApp: Assumptions!$C$38
Name K_PermitRate26: Assumptions!$C$41
Name K_PermitRate27: Assumptions!$C$42
Name K_Permits2025: Assumptions!$C$43
Name K_Inv2019: Assumptions!$C$44
Name K_Inv2025: Assumptions!$C$45
Name K_InvEst2025: Assumptions!$C$46
Name K_InvFlat: Assumptions!$C$47
Name K_Meals2019: Assumptions!$C$48
Name K_Meals2025: Assumptions!$C$49
Name K_MealsGrowth: Assumptions!$C$50
Name K_MealsPerSqft: Assumptions!$C$51
Name R_LRresid2025: Assumptions!$C$52
Name R_LRbase: Assumptions!$C$53
Name R_SA2026: Assumptions!$C$54
Name R_SA2027: Assumptions!$C$55
Name R_SAbase: Assumptions!$C$56
Name R_BudgetRatio: Assumptions!$C$59
Name R_OtherSurplus: Assumptions!$C$60
Name R_ApprShare: Assumptions!$C$61
Name K_ChcaStart: Assumptions!$C$64
Name K_ChcaSpan: Assumptions!$C$65
Name K_ChcaDollarYr: Assumptions!$C$66
Name K_ChcaUnits: Assumptions!$C$67
Name K_ChcaSPU: Assumptions!$C$68
Name K_ChcaEmp: Assumptions!$C$69
Name K_pD: Assumptions!$C$72
Name K_psD: Assumptions!$C$73
Name K_TownFTE: Assumptions!$C$74
Name K_BasePay: Assumptions!$C$75
Name K_BenLoad: Assumptions!$C$76

Sheet Start here
A1: Brookline's finances to 2040: the forecast as a spreadsheet
A3: What this is
A5: This workbook is the Forecast Explorer (brooklinefuture.org/forecast/explorer) in spreadsheet form. It runs the same forecast, from the same numbers, with every step a formula you can follow.
A6: How to use it
A7: 1. Go to Settings and change any yellow cell. Each setting is a control on the Explorer, with the same choices.
A8: 2. Read the result on Forecast: revenue, spending and the room (revenue minus spending) for every year to FY2040. A negative room means spending runs ahead of revenue that year.
A9: 3. To start over, copy the Base case column on Settings back into Your value.
A10: The sheets
A11: Settings: the 23 settings, their base case values and allowed ranges, and, below them, how the model reads each one.
A12: Forecast: the results at the top, then every working step the model takes, row by row, in the order the Explorer's engine takes them.
A13: Revenue build: property tax year by year. Last year's levy limit, plus 2.5%, plus new growth in five kinds, plus the May 2026 override; then the homes and commercial space that new growth stands for, and the permit fees and meals tax that come with it.
A14: Worked example: one year, FY2033, followed step by step from the levy to the room, every number a live cell.
... A27: Voter-approved debt exclusions run through the General Fund but pay for nothing except their own building debt, so the forecast sets them aside on both the revenue and the spending side; they would add the same amount to each.

Sheet Settings
A1: Settings
A2: Change the yellow cells; the Forecast sheet updates. Each setting matches a control on the Forecast Explorer, with the same choices. To return to the base case, copy the Base case column back into Your value.
A4: Setting | B4: Your value | C4: Base case | D4: Allowed | E4: Works out to | F4: What it means
A6: The big six
A7: Pay raises compared with the base case | B7: 0 | C7: 0 | D7: -1.5 to +2.0 points | E7: =PayTown | F7: Moves every employee group's yearly raise by the same amount. The base case starts from the Town's 3.0% bargaining target, with schools and Public Safety above it (next group).
A8: Pension savings after full funding | B8: Moved to retiree health (OPEB), the Town's plan; once it's paid off, held for a decision | C8: Moved to retiree health (OPEB), the Town's plan; once it's paid off, held for a decision | D8: Choose from the list | F8: The pension system reaches full funding in FY2030. The Town plans to use the money it stops paying toward pensions to pay down its retiree health (OPEB) liability instead. Once that is paid off, the base case keeps the money in the budget for a decision then; the second choice counts it as room.
A9: School staff as enrollment falls | B9: Fall half as fast as enrollment, as in FY2019 to FY2025 | C9: Fall half as fast as enrollment, as in FY2019 to FY2025 | D9: Choose from the list | F9: From FY2019 to FY2025 enrollment fell 10.6% and school staff 5.0%, about half as fast. The base case continues that pattern; students from new homes are staffed in full. The School Department's own plan holds staff at the FY2027 level.
A10: Health premium growth, FY2030 on | B10: 0.08 | C10: 0.08 | D10: 5% to 12% | F10: Yearly rise in health insurance premiums. The 25-year average is 6.5%; recent years ran 10 to 12%.
A11: Property tax new growth, tenths of a point above the recent trend | B11: 0 | C11: 0 | D11: -6 to 13 | E11: =GrowthRate | F11: Tax base added each year by construction, renovation and business equipment, as a share of last year's levy. 0 is the recent trend; each step is a tenth of a percentage point.
A12: New homes built | B12: As expected | C12: As expected | D12: Choose from the list | F12: Scales only the new-homes part of new growth (about a sixth of it), including any added growth above; renovation, commercial space and business equipment continue at their pace. The enrollment forecast is left as it is.
A14: The next five
A15: School pay above the Town target | B15: 0.007 | C15: 0.007 | D15: 0 to 2.5 points | E15: =PayTown+SchDrift | F15: The base case puts school pay 0.7 point above the Town target (3.7%). The schools' own forecast implies about 2 points.
A16: Public Safety pay above the Town target | B16: 0.005 | C16: 0.005 | D16: 0 to 2.5 points | E16: =PayTown+PSPrem | F16: The base case puts Public Safety pay 0.5 point above the target (3.5%). Police and fire cost per position grew about 3.3% a year from FY2011 to FY2025; the agreed fire steps and police refills are counted on top.
A17: Local receipts growth | B17: 0.017648984 | C17: 0.017648984 | D17: 1% to 6% | F17: Fees, excise and other local revenue, apart from meals tax and building permits. Base: the FY2019 to FY2025 rate.
A18: Inflation | B18: 0.025 | C18: 0.025 | D18: 1.5% to 5% | F18: Price growth for everything that is not pay: supplies, utilities, contracts.
A19: State aid growth | B19: 0.025 | C19: 0.025 | D19: 0% to 6% | F19: Chapter 70 school aid and unrestricted local aid, from the adopted FY2027 figure. Base: 2.5%, the Town plan's rate.
A21: Everything else
A22: Where added growth comes from | B22: Today's mix | C22: Today's mix | D22: Choose from the list | F22: Only matters when new growth is set above the recent trend. New homes add students and services; commercial space pays a higher tax rate and costs less to serve.
A23: Students from added homes | B23: Each brings new staff at today's ratio | C23: Each brings new staff at today's ratio | D23: Choose from the list | F23: Students from added homes can fill seats left open as enrollment falls: all of them with staff held at the FY2027 level, half of them with staff falling half as fast. Has no effect when staff follow enrollment fully.
A24: School enrollment forecast | B24: NESDEC (declines) | C24: NESDEC (declines) | D24: Choose from the list | F24: Which enrollment path the schools serve.
A25: Families moving in, change in each class a year | B25: 0 | C25: 0 | D25: -1 to +2 points | F25: How much each class grows or shrinks each year from families moving in and out, beyond what NESDEC assumes, for children of every age from birth on, so kindergartners per birth move with it. Since COVID classes have grown about 0.35 point a year faster than NESDEC assumes. Changes the NESDEC path only.
A26: Health premium growth, FY2028 and FY2029 | B26: 0.12 | C26: 0.12 | D26: 6% to 14% | F26: The Town's own forecast for the next two years.
A27: School non-personnel costs above inflation | B27: 0 | C27: 0 | D27: 0 to 3 points | F27: Special education placements and transportation have at times grown faster than prices in general.
A28: Capital funding | B28: The 6.6% policy, from FY2028 | C28: The 6.6% policy, from FY2028 | D28: Choose from the list | F28: The Select Board's policy puts 6.6% of the prior year's net revenue into capital from FY2028; holding capital at the Town's six-year table's dollars comes to about 6% of this forecast's net revenue.
A29: Town cost of serving a new home (FY2025 $) | B29: 660 | C29: 660 | D29: $200 to $1,200 | F29: Town department cost per added home a year, before schools. The forecast leaves out fire's share, about a fifth, since fire is counted in steps under Police and fire staffing, and police's share too when police grow with homes.
A30: Police and fire staffing | B30: FY2027 budget, plus a fire company at about 31,200 homes | C30: FY2027 budget, plus a fire company at about 31,200 homes | D30: Choose from the list | F30: The FY2027 budget funds 128 sworn police and 160 firefighters. A fire company (20 firefighters) is added when the town reaches about 31,200 homes. Police growing with homes keeps 4.42 officers per 1,000 homes; restoring earlier staffing adds 16 positions from FY2028.
A31: Chestnut Hill redevelopment | B31: Approved program, Town Meeting May 2026 | C31: Approved program, Town Meeting May 2026 | D31: Choose from the list | F31: 266 homes and a 200-room hotel, arriving FY2032 to FY2034. The estimates differ only in revenue.
A32: Pension full funding slips | B32: On schedule, FY2030 | C32: On schedule, FY2030 | D32: Choose from the list | F32: If investment returns fall short, full pension contributions continue for longer.
A33: New growth in FY2027 and FY2028 | B33: The recent trend (the base case) | C33: The recent trend (the base case) | D33: Choose from the list | F33: Building permits show new growth about two years ahead. The 2024 and 2025 permits point to real estate new growth well below the trend in FY2027 and FY2028; business equipment stays at its trend. The shortfall then carries through every later levy. The Explorer does not have this setting.
A34: A further override (first-year dollars) | B34: 0 | C34: 0 | D34: $0 to $30,000,000 | F34: An operating override added to the levy, growing 2.5% a year after. The forecast itself never assumes one.
A35: First year of that override | B35: 2031 | C35: 2031 | D35: 2029 to 2035 | F35: Only matters when the override above is more than zero.
A37: How the model reads these settings (worked out, do not edit)
A38: Each line turns a choice above into the value the Forecast sheet uses.
A39: Pay growth, Town staff | B39: =K_BasePay+In_pay
A40: Public Safety above the target | B40: =In_ps_premium
A41: Schools above the target | B41: =In_school_drift
A42: Health premiums, FY2030 on | B42: =In_premium_long
A43: Health premiums, FY2028 and FY2029 | B43: =In_premium_near
A44: Inflation | B44: =In_cpi
A45: School non-personnel above inflation | B45: =In_np_extra
...

Sheet Forecast
A1: Forecast, FY2027 to FY2040
A2: Revenue and spending of the General Fund, with voter-approved debt exclusions set aside on both sides. Everything here is a live formula driven by the Settings sheet, the Revenue build sheet and the Assumptions sheet. FY2026 appears only because the free cash cycle and new growth start from it.
C4: 2026 | D4: 2027 | E4: 2028 | F4: 2029 | G4: 2030 | H4: 2031 | I4: 2032 | J4: 2033 | K4: 2034 | L4: 2035 | M4: 2036 | N4: 2037 | O4: 2038 | P4: 2039 | Q4: 2040
A6: Revenue
A7: Property tax (debt exclusions set aside) | D7: =D47-D48 | E7: =E47-E48 | F7: =F47-F48 | G7: =G47-G48 | H7: =H47-H48 | I7: =I47-I48 | J7: =J47-J48 | K7: =K47-K48 | ... Q7: =Q47-Q48
A8: State aid | D8: =D72 | E8: =E72 | F8: =F72 | G8: =G72 | H8: =H72 | I8: =I72 | J8: =J72 | K8: =K72 | ... Q8: =Q72
A9: Local receipts, as budgeted | D9: =D76 | E9: =E76 | F9: =F76 | G9: =G76 | H9: =H76 | I9: =I76 | J9: =J76 | K9: =K76 | ... Q9: =Q76
A10: Free cash | D10: =D77 | E10: =E77 | F10: =F77 | G10: =G77 | H10: =H77 | I10: =I77 | J10: =J77 | K10: =K77 | ... Q10: =Q77
A11: Other available funds | D11: =D49 | E11: =E49 | F11: =F49 | G11: =G49 | H11: =H49 | I11: =I49 | J11: =J49 | K11: =K49 | ... Q11: =Q49
A12: A further override | D12: =D74 | E12: =E74 | F12: =F74 | G12: =G74 | H12: =H74 | I12: =I74 | J12: =J74 | K12: =K74 | ... Q12: =Q74
A13: Total revenue | D13: =D78-D48 | E13: =E78-E48 | F13: =F78-F48 | G13: =G78-G48 | H13: =H78-H48 | I13: =I78-I48 | J13: =J78-J48 | K13: =K78-K48 | ... Q13: =Q78-Q48
A15: Spending
A16: Town departments, today's services | D16: =A_TD*(K_pD*D66+(1-K_pD)*D58)+D37 | E16: =A_TD*(K_pD*E66+(1-K_pD)*E58)+E37 | F16: =A_TD*(K_pD*F66+(1-K_pD)*F58)+F37 | G16: =A_TD*(K_pD*G66+(1-K_pD)*G58)+G37 | H16: =A_TD*(K_pD*H66+(1-K_pD)*H58)+H37 | I16: =A_TD*(K_pD*I66+(1-K_pD)*I58)+I37 | J16: =A_TD*(K_pD*J66+(1-K_pD)*J58)+J37 | K16: =A_TD*(K_pD*K66+(1-K_pD)*K58)+K37 | ... Q16: =A_TD*(K_pD*Q66+(1-K_pD)*Q58)+Q37
A17: Town services for added homes and businesses | D17: =(D34*CostHome*(1-K_PSShare*(FireStep*(1-K_PSSharePol)+PoliceStep*K_PSSharePol))+D67*K_CostPerEmp)*PayToFY27*D55+D36+D39 | E17: =(E34*CostHome*(1-K_PSShare*(FireStep*(1-K_PSSharePol)+PoliceStep*K_PSSharePol))+E67*K_CostPerEmp)*PayToFY27*E55+K_Permit*MAX(E45/E46-1,0)*E55+E36+E39 | F17: =(F34*CostHome*(1-K_PSShare*(FireStep*(1-K_PSSharePol)+PoliceStep*K_PSSharePol))+F67*K_CostPerEmp)*PayToFY27*F55+K_Permit*MAX(F45/F46-1,0)*F55+F36+F39 | G17: =(G34*CostHome*(1-K_PSShare*(FireStep*(1-K_PSSharePol)+PoliceStep*K_PSSharePol))+G67*K_CostPerEmp)*PayToFY27*G55+K_Permit*MAX(G45/G46-1,0)*G55+G36+G39 | H17: =(H34*CostHome*(1-K_PSShare*(FireStep*(1-K_PSSharePol)+PoliceStep*K_PSSharePol))+H67*K_CostPerEmp)*PayToFY27*H55+K_Permit*MAX(H45/H46-1,0)*H55+H36+H39 | I17: =(I34*CostHome*(1-K_PSShare*(FireStep*(1-K_PSSharePol)+PoliceStep*K_PSSharePol))+I67*K_CostPerEmp)*PayToFY27*I55+K_Permit*MAX(I45/I46-1,0)*I55+I36+I39 | J17: =(J34*CostHome*(1-K_PSShare*(FireStep*(1-K_PSSharePol)+PoliceStep*K_PSSharePol))+J67*K_CostPerEmp)*PayToFY27*J55+K_Permit*MAX(J45/J46-1,0)*J55+J36+J39 | K17: =(K34*CostHome*(1-K_PSShare*(FireStep*(1-K_PSSharePol)+PoliceStep*K_PSSharePol))+K67*K_CostPerEmp)*PayToFY27*K55+K_Permit*MAX(K45/K46-1,0)*K55+K36+K39 | L17: =(L34*CostHome*(1-K_PSShare*(FireStep*(1-K_PSSharePol)+PoliceStep*K_PSSharePol))+L67*K_CostPerEmp)*PayToFY27*L55+K_Permit*MAX(L45/L46-1,0)*L55+L36+L39 | ... Q17: =(Q34*CostHome*(1-K_PSShare*(FireStep*(1-K_PSSharePol)+PoliceStep*K_PSSharePol))+Q67*K_CostPerEmp)*PayToFY27*Q55+K_Permit*MAX(Q45/Q46-1,0)*Q55+Q36+Q39
A18: Schools | D18: =A_Sch*(K_SPS*D57*D33/Staff27+(1-K_SPS)*D59*((1-K_V)+K_V*D32/Enroll27))+D63*(K_FillSeat-A_Sch*(1-K_SPS)*K_V/Enroll27)*D57/$D$57 | E18: =A_Sch*(K_SPS*E57*E33/Staff27+(1-K_SPS)*E59*((1-K_V)+K_V*E32/Enroll27))+E63*(K_FillSeat-A_Sch*(1-K_SPS)*K_V/Enroll27)*E57/$D$57 | F18: =A_Sch*(K_SPS*F57*F33/Staff27+(1-K_SPS)*F59*((1-K_V)+K_V*F32/Enroll27))+F63*(K_FillSeat-A_Sch*(1-K_SPS)*K_V/Enroll27)*F57/$D$57 | G18: =A_Sch*(K_SPS*G57*G33/Staff27+(1-K_SPS)*G59*((1-K_V)+K_V*G32/Enroll27))+G63*(K_FillSeat-A_Sch*(1-K_SPS)*K_V/Enroll27)*G57/$D$57 | H18: =A_Sch*(K_SPS*H57*H33/Staff27+(1-K_SPS)*H59*((1-K_V)+K_V*H32/Enroll27))+H63*(K_FillSeat-A_Sch*(1-K_SPS)*K_V/Enroll27)*H57/$D$57 | I18: =A_Sch*(K_SPS*I57*I33/Staff27+(1-K_SPS)*I59*((1-K_V)+K_V*I32/Enroll27))+I63*(K_FillSeat-A_Sch*(1-K_SPS)*K_V/Enroll27)*I57/$D$57 | J18: =A_Sch*(K_SPS*J57*J33/Staff27+(1-K_SPS)*J59*((1-K_V)+K_V*J32/Enroll27))+J63*(K_FillSeat-A_Sch*(1-K_SPS)*K_V/Enroll27)*J57/$D$57 | K18: =A_Sch*(K_SPS*K57*K33/Staff27+(1-K_SPS)*K59*((1-K_V)+K_V*K32/Enroll27))+K63*(K_FillSeat-A_Sch*(1-K_SPS)*K_V/Enroll27)*K57/$D$57 | ... Q18: =A_Sch*(K_SPS*Q57*Q33/Staff27+(1-K_SPS)*Q59*((1-K_V)+K_V*Q32/Enroll27))+Q63*(K_FillSeat-A_Sch*(1-K_SPS)*K_V/Enroll27)*Q57/$D$57
A19: Health insurance | D19: =A_GH*D71*D60 | E19: =A_GH*E71*E60 | F19: =A_GH*F71*F60 | G19: =A_GH*G71*G60 | H19: =A_GH*H71*H60 | I19: =A_GH*I71*I60 | J19: =A_GH*J71*J60 | K19: =A_GH*K71*K60 | ... Q19: =A_GH*Q71*Q60
A20: Benefits for staff added by growth | D20: =(D17-D36-D39)*K_BenLoad | E20: =(E17-E36-E39)*K_BenLoad | F20: =(F17-F36-F39)*K_BenLoad | G20: =(G17-G36-G39)*K_BenLoad | H20: =(H17-H36-H39)*K_BenLoad | I20: =(I17-I36-I39)*K_BenLoad | J20: =(J17-J36-J39)*K_BenLoad | K20: =(K17-K36-K39)*K_BenLoad | ... Q20: =(Q17-Q36-Q39)*K_BenLoad
A21: Pensions | D21: =A_Pen | E21: =E69 | F21: =F69 | G21: =IF(AND(PensionSlip>0,G$4>=2030,G$4<=2030+PensionSlip),PenNC30+PenSlipPay,G69) | H21: =IF(AND(PensionSlip>0,H$4>=2030,H$4<=2030+PensionSlip),H69+PenSlipPay,H69) | I21: =IF(AND(PensionSlip>0,I$4>=2030,I$4<=2030+PensionSlip),I69+PenSlipPay,I69) | J21: =IF(AND(PensionSlip>0,J$4>=2030,J$4<=2030+PensionSlip),J69+PenSlipPay,J69) | K21: =IF(AND(PensionSlip>0,K$4>=2030,K$4<=2030+PensionSlip),K69+PenSlipPay,K69) | L21: =IF(AND(PensionSlip>0,L$4>=2030,L$4<=2030+PensionSlip),L69+PenSlipPay,L69) | M21: =IF(AND(PensionSlip>0,M$4>=2030,M$4<=2030+PensionSlip),M69+PenSlipPay,M69) | N21: =IF(AND(PensionSlip>0,N$4>=2030,N$4<=2030+PensionSlip),N69+PenSlipPay,N69) | O21: =IF(AND(PensionSlip>0,O$4>=2030,O$4<=2030+PensionSlip),O69+PenSlipPay,O69) | ... Q21: =IF(AND(PensionSlip>0,Q$4>=2030,Q$4<=2030+PensionSlip),Q69+PenSlipPay,Q69)
A22: Retiree health (OPEB) | D22: =A_OPEB | E22: =IF(AND(OpebHold=1,Redirect=1),E85,E86) | F22: =IF(AND(OpebHold=1,Redirect=1),F85,F86) | G22: =IF(AND(OpebHold=1,Redirect=1),G85,G86) | H22: =IF(AND(OpebHold=1,Redirect=1),H85,H86) | I22: =IF(AND(OpebHold=1,Redirect=1),I85,I86) | J22: =IF(AND(OpebHold=1,Redirect=1),J85,J86) | K22: =IF(AND(OpebHold=1,Redirect=1),K85,K86) | L22: =IF(AND(OpebHold=1,Redirect=1),L85,L86) | ... Q22: =IF(AND(OpebHold=1,Redirect=1),Q85,Q86)
A23: Other benefits | D23: =A_OB | E23: =Data!E28 | F23: =Data!F28 | G23: =Data!G28 | H23: =Data!H28 | I23: =Data!$H$28*I68/$H$68 | J23: =Data!$H$28*J68/$H$68 | K23: =Data!$H$28*K68/$H$68 | L23: =Data!$H$28*L68/$H$68 | M23: =Data!$H$28*M68/$H$68 | N23: =Data!$H$28*N68/$H$68 | O23: =Data!$H$28*O68/$H$68 | P23: =Data!$H$28*P68/$H$68 | Q23: =Data!$H$28*Q68/$H$68
A24: Debt within the levy | D24: =A_Debt | E24: =Data!E29 | F24: =Data!F29 | G24: =Data!G29 | H24: =Data!H29 | I24: =Data!I29 | J24: =Data!$I$29*(1+K_DebtGrowth)^(J$4-2032) | K24: =Data!$I$29*(1+K_DebtGrowth)^(K$4-2032) | L24: =Data!$I$29*(1+K_DebtGrowth)^(L$4-2032) | M24: =Data!$I$29*(1+K_DebtGrowth)^(M$4-2032) | N24: =Data!$I$29*(1+K_DebtGrowth)^(N$4-2032) | O24: =Data!$I$29*(1+K_DebtGrowth)^(O$4-2032) | P24: =Data!$I$29*(1+K_DebtGrowth)^(P$4-2032) | Q24: =Data!$I$29*(1+K_DebtGrowth)^(Q$4-2032)
A25: Capital, reserves and other | D25: =A_Other | E25: =Data!E30+IF(CapFull=1,MAX(K_CIP*D79-E24-Data!E31,0),0)+K_Reserve*D79-Data!E32+E77-(Data!E34+K_FCDeposit*Data!E33+K_FCReserve*D79) | F25: =Data!F30+IF(CapFull=1,MAX(K_CIP*E79-F24-Data!F31,0),0)+K_Reserve*E79-Data!F32+F77-(Data!F34+K_FCDeposit*Data!F33+K_FCReserve*E79) | G25: =Data!G30+IF(CapFull=1,MAX(K_CIP*F79-G24-Data!G31,0),0)+K_Reserve*F79-Data!G32+G77-(Data!G34+K_FCDeposit*Data!G33+K_FCReserve*F79) | H25: =Data!H30+IF(CapFull=1,MAX(K_CIP*G79-H24-Data!H31,0),0)+K_Reserve*G79-Data!H32+H77-(Data!H34+K_FCDeposit*Data!H33+K_FCReserve*G79) | I25: =Data!I30+IF(CapFull=1,MAX(K_CIP*H79-I24-Data!I31,0),0)+K_Reserve*H79-Data!H32+K_GenFY31*(H79/$G$79-1)+K_NonAppFY31*((1+K_NonAppG)^(I$4-2031)-1)+I77-(Data!I34+K_FCDeposit*K_GenFY31*H79/$G$79+K_FCReserve*H79) | J25: =Data!J30+IF(CapFull=1,MAX(K_CIP*I79-J24-Data!J31,0),0)+K_Reserve*I79-Data!H32+K_GenFY31*(I79/$G$79-1)+K_NonAppFY31*((1+K_NonAppG)^(J$4-2031)-1)+J77-(Data!J34+K_FCDeposit*K_GenFY31*I79/$G$79+K_FCReserve*I79) | K25: =Data!K30+IF(CapFull=1,MAX(K_CIP*J79-K24-Data!K31,0),0)+K_Reserve*J79-Data!H32+K_GenFY31*(J79/$G$79-1)+K_NonAppFY31*((1+K_NonAppG)^(K$4-2031)-1)+K77-(Data!K34+K_FCDeposit*K_GenFY31*J79/$G$79+K_FCReserve*J79) | L25: =Data!L30+IF(CapFull=1,MAX(K_CIP*K79-L24-Data!L31,0),0)+K_Reserve*K79-Data!H32+K_GenFY31*(K79/$G$79-1)+K_NonAppFY31*((1+K_NonAppG)^(L$4-2031)-1)+L77-(Data!L34+K_FCDeposit*K_GenFY31*K79/$G$79+K_FCReserve*K79) | M25: =Data!M30+IF(CapFull=1,MAX(K_CIP*L79-M24-Data!M31,0),0)+K_Reserve*L79-Data!H32+K_GenFY31*(L79/$G$79-1)+K_NonAppFY31*((1+K_NonAppG)^(M$4-2031)-1)+M77-(Data!M34+K_FCDeposit*K_GenFY31*L79/$G$79+K_FCReserve*L79) | N25: =Data!N30+IF(CapFull=1,MAX(K_CIP*M79-N24-Data!N31,0),0)+K_Reserve*M79-Data!H32+K_GenFY31*(M79/$G$79-1)+K_NonAppFY31*((1+K_NonAppG)^(N$4-2031)-1)+N77-(Data!N34+K_FCDeposit*K_GenFY31*M79/$G$79+K_FCReserve*M79) | O25: =Data!O30+IF(CapFull=1,MAX(K_CIP*N79-O24-Data!O31,0),0)+K_Reserve*N79-Data!H32+K_GenFY31*(N79/$G$79-1)+K_NonAppFY31*((1+K_NonAppG)^(O$4-2031)-1)+O77-(Data!O34+K_FCDeposit*K_GenFY31*N79/$G$79+K_FCReserve*N79) | P25: =Data!P30+IF(CapFull=1,MAX(K_CIP*O79-P24-Data!P31,0),0)+K_Reserve*O79-Data!H32+K_GenFY31*(O79/$G$79-1)+K_NonAppFY31*((1+K_NonAppG)^(P$4-2031)-1)+P77-(Data!P34+K_FCDeposit*K_GenFY31*O79/$G$79+K_FCReserve*O79) | Q25: =Data!Q30+IF(CapFull=1,MAX(K_CIP*P79-Q24-Data!Q31,0),0)+K_Reserve*P79-Data!H32+K_GenFY31*(P79/$G$79-1)+K_NonAppFY31*((1+K_NonAppG)^(Q$4-2031)-1)+Q77-(Data!Q34+K_FCDeposit*K_GenFY31*P79/$G$79+K_FCReserve*P79)
A26: Total spending | D26: =D16+D17+D18+D19+D20+D21+D22+D23+D24+D25 | E26: =E16+E17+E18+E19+E20+E21+E22+E23+E24+E25 | F26: =F16+F17+F18+F19+F20+F21+F22+F23+F24+F25 | G26: =G16+G17+G18+G19+G20+G21+G22+G23+G24+G25 | H26: =H16+H17+H18+H19+H20+H21+H22+H23+H24+H25 | I26: =I16+I17+I18+I19+I20+I21+I22+I23+I24+I25 | J26: =J16+J17+J18+J19+J20+J21+J22+J23+J24+J25 | K26: =K16+K17+K18+K19+K20+K21+K22+K23+K24+K25 | ... Q26: =Q16+Q17+Q18+Q19+Q20+Q21+Q22+Q23+Q24+Q25
A29: Room: revenue minus spending | D29: =D13-D26 | E29: =E13-E26 | F29: =F13-F26 | G29: =G13-G26 | H29: =H13-H26 | I29: =I13-I26 | J29: =J13-J26 | K29: =K13-K26 | ... Q29: =Q13-Q26
A31: Context
A32: School enrollment served | C32: =C61+C62 | D32: =D61+D62 | E32: =E61+E62 | F32: =F61+F62 | G32: =G61+G62 | H32: =H61+H62 | I32: =I61+I62 | J32: =J61+J62 | ... Q32: =Q61+Q62
A33: School staff | C33: =Staff27*(1-K_V)+K_V*C65 | D33: =Staff27*(1-K_V)+K_V*D65 | E33: =Staff27*(1-K_V)+K_V*E65 | F33: =Staff27*(1-K_V)+K_V*F65 | G33: =Staff27*(1-K_V)+K_V*G65 | H33: =Staff27*(1-K_V)+K_V*H65 | I33: =Staff27*(1-K_V)+K_V*I65 | J33: =Staff27*(1-K_V)+K_V*J65 | ... Q33: =Staff27*(1-K_V)+K_V*Q65
A34: Added homes since FY2027, including Chestnut Hill | D34: =D51+K_ChcaUnits*D54 | E34: =E51+K_ChcaUnits*E54 | F34: =F51+K_ChcaUnits*F54 | G34: =G51+K_ChcaUnits*G54 | H34: =H51+K_ChcaUnits*H54 | I34: =I51+K_ChcaUnits*I54 | J34: =J51+K_ChcaUnits*J54 | K34: =K51+K_ChcaUnits*K54 | ... Q34: =Q51+K_ChcaUnits*Q54
A35: Homes in town, including Chestnut Hill | C35: =K_Homes25+SUM($C42:C42)+K_ChcaUnits*C54 | D35: =K_Homes25+SUM($C42:D42)+K_ChcaUnits*D54 | E35: =K_Homes25+SUM($C42:E42)+K_ChcaUnits*E54 | F35: =K_Homes25+SUM($C42:F42)+K_ChcaUnits*F54 | G35: =K_Homes25+SUM($C42:G42)+K_ChcaUnits*G54 | H35: =K_Homes25+SUM($C42:H42)+K_ChcaUnits*H54 | I35: =K_Homes25+SUM($C42:I42)+K_ChcaUnits*I54 | J35: =K_Homes25+SUM($C42:J42)+K_ChcaUnits*J54 | ... Q35: =K_Homes25+SUM($C42:Q42)+K_ChcaUnits*Q54
A36: Fire company (included in Town services for growth) | D36: =0 | E36: =IF(AND(FireStep=1,E35>=K_FireHomes),K_FireCost*PSPayToFY27*E56,0) | F36: =IF(AND(FireStep=1,F35>=K_FireHomes),K_FireCost*PSPayToFY27*F56,0) | G36: =IF(AND(FireStep=1,G35>=K_FireHomes),K_FireCost*PSPayToFY27*G56,0) | H36: =IF(AND(FireStep=1,H35>=K_FireHomes),K_FireCost*PSPayToFY27*H56,0) | I36: =IF(AND(FireStep=1,I35>=K_FireHomes),K_FireCost*PSPayToFY27*I56,0) | J36: =IF(AND(FireStep=1,J35>=K_FireHomes),K_FireCost*PSPayToFY27*J56,0) | K36: =IF(AND(FireStep=1,K35>=K_FireHomes),K_FireCost*PSPayToFY27*K56,0) | L36: =IF(AND(FireStep=1,L35>=K_FireHomes),K_FireCost*PSPayToFY27*L56,0) | ... Q36: =IF(AND(FireStep=1,Q35>=K_FireHomes),K_FireCost*PSPayToFY27*Q56,0)
A37: Police and fire: restored staffing if chosen, and commitments already agreed (in today's services) | D37: =0 | E37: =PSRestore*K_PSRestoreN*K_PSPos*PSPayToFY27*E56+K_FireSteps*E56/$E$56+(1-PSRestore)*K_PolRefill28*K_PSPos*PSPayToFY27*E56 | F37: =PSRestore*K_PSRestoreN*K_PSPos*PSPayToFY27*F56+K_FireSteps*F56/$E$56+(1-PSRestore)*K_PolRefill29*K_PSPos*PSPayToFY27*F56 | G37: =PSRestore*K_PSRestoreN*K_PSPos*PSPayToFY27*G56+K_FireSteps*G56/$E$56+(1-PSRestore)*K_PolRefill29*K_PSPos*PSPayToFY27*G56 | H37: =PSRestore*K_PSRestoreN*K_PSPos*PSPayToFY27*H56+K_FireSteps*H56/$E$56+(1-PSRestore)*K_PolRefill29*K_PSPos*PSPayToFY27*H56 | I37: =PSRestore*K_PSRestoreN*K_PSPos*PSPayToFY27*I56+K_FireSteps*I56/$E$56+(1-PSRestore)*K_PolRefill29*K_PSPos*PSPayToFY27*I56 | J37: =PSRestore*K_PSRestoreN*K_PSPos*PSPayToFY27*J56+K_FireSteps*J56/$E$56+(1-PSRestore)*K_PolRefill29*K_PSPos*PSPayToFY27*J56 | K37: =PSRestore*K_PSRestoreN*K_PSPos*PSPayToFY27*K56+K_FireSteps*K56/$E$56+(1-PSRestore)*K_PolRefill29*K_PSPos*PSPayToFY27*K56 | L37: =PSRestore*K_PSRestoreN*K_PSPos*PSPayToFY27*L56+K_FireSteps*L56/$E$56+(1-PSRestore)*K_PolRefill29*K_PSPos*PSPayToFY27*L56 | M37: =PSRestore*K_PSRestoreN*K_PSPos*PSPayToFY27*M56+K_FireSteps*M56/$E$56+(1-PSRestore)*K_PolRefill29*K_PSPos*PSPayToFY27*M56 | ... Q37: =PSRestore*K_PSRestoreN*K_PSPos*PSPayToFY27*Q56+K_FireSteps*Q56/$E$56+(1-PSRestore)*K_PolRefill29*K_PSPos*PSPayToFY27*Q56
A38: Police officers added to hold the peer ratio | D38: =0 | E38: =IF(PoliceStep=1,MAX(INT(E35*K_PolRatio/1000+1E-9)-K_PolBudget-K_PolRefill28,0),0) | F38: =IF(PoliceStep=1,MAX(INT(F35*K_PolRatio/1000+1E-9)-K_PolBudget-K_PolRefill29,0),0) | G38: =IF(PoliceStep=1,MAX(INT(G35*K_PolRatio/1000+1E-9)-K_PolBudget-K_PolRefill29,0),0) | H38: =IF(PoliceStep=1,MAX(INT(H35*K_PolRatio/1000+1E-9)-K_PolBudget-K_PolRefill29,0),0) | I38: =IF(PoliceStep=1,MAX(INT(I35*K_PolRatio/1000+1E-9)-K_PolBudget-K_PolRefill29,0),0) | J38: =IF(PoliceStep=1,MAX(INT(J35*K_PolRatio/1000+1E-9)-K_PolBudget-K_PolRefill29,0),0) | K38: =IF(PoliceStep=1,MAX(INT(K35*K_PolRatio/1000+1E-9)-K_PolBudget-K_PolRefill29,0),0) | L38: =IF(PoliceStep=1,MAX(INT(L35*K_PolRatio/1000+1E-9)-K_PolBudget-K_PolRefill29,0),0) | M38: =IF(PoliceStep=1,MAX(INT(M35*K_PolRatio/1000+1E-9)-K_PolBudget-K_PolRefill29,0),0) | ... Q38: =IF(PoliceStep=1,MAX(INT(Q35*K_PolRatio/1000+1E-9)-K_PolBudget-K_PolRefill29,0),0)
A39: Police added (included in Town services for growth) | D39: =D38*K_PSPos*PSPayToFY27*D56 | E39: =E38*K_PSPos*PSPayToFY27*E56 | F39: =F38*K_PSPos*PSPayToFY27*F56 | G39: =G38*K_PSPos*PSPayToFY27*G56 | H39: =H38*K_PSPos*PSPayToFY27*H56 | I39: =I38*K_PSPos*PSPayToFY27*I56 | J39: =J38*K_PSPos*PSPayToFY27*J56 | K39: =K38*K_PSPos*PSPayToFY27*K56 | ... Q39: =Q38*K_PSPos*PSPayToFY27*Q56
A41: How the model works it out
A42: Homes added that year (Revenue build) | C42: =ROUND('Revenue build'!C45,0) | D42: =ROUND('Revenue build'!D45,0) | E42: =ROUND('Revenue build'!E45,0) | F42: =ROUND('Revenue build'!F45,0) | G42: =ROUND('Revenue build'!G45,0) | H42: =ROUND('Revenue build'!H45,0) | I42: =ROUND('Revenue build'!I45,0) | J42: =ROUND('Revenue build'!J45,0) | ... Q42: =ROUND('Revenue build'!Q45,0)
A43: Homes added that year at the recent trend (Revenue build) | C43: =ROUND('Revenue build'!C66,0) | D43: =ROUND('Revenue build'!D66,0) | E43: =ROUND('Revenue build'!E66,0) | F43: =ROUND('Revenue build'!F66,0) | G43: =ROUND('Revenue build'!G66,0) | H43: =ROUND('Revenue build'!H66,0) | I43: =ROUND('Revenue build'!I66,0) | J43: =ROUND('Revenue build'!J66,0) | ... Q43: =ROUND('Revenue build'!Q66,0)
A44: Commercial square feet added that year (Revenue build) | C44: =ROUND('Revenue build'!C46,0) | D44: =ROUND('Revenue build'!D46,0) | E44: =ROUND('Revenue build'!E46,0) | F44: =ROUND('Revenue build'!F46,0) | G44: =ROUND('Revenue build'!G46,0) | H44: =ROUND('Revenue build'!H46,0) | I44: =ROUND('Revenue build'!I46,0) | J44: =ROUND('Revenue build'!J46,0) | ... Q44: =ROUND('Revenue build'!Q46,0)
A45: Real-estate new growth (Revenue build) | C45: ='Revenue build'!C47 | D45: ='Revenue build'!D47 | E45: ='Revenue build'!E47 | F45: ='Revenue build'!F47 | G45: ='Revenue build'!G47 | H45: ='Revenue build'!H47 | I45: ='Revenue build'!I47 | J45: ='Revenue build'!J47 | ... Q45: ='Revenue build'!Q47
A46: Real-estate new growth at the recent trend (Revenue build) | C46: ='Revenue build'!C67 | D46: ='Revenue build'!D67 | E46: ='Revenue build'!E67 | F46: ='Revenue build'!F67 | G46: ='Revenue build'!G67 | H46: ='Revenue build'!H67 | I46: ='Revenue build'!I67 | J46: ='Revenue build'!J67 | ... Q46: ='Revenue build'!Q67
A47: Property tax, all (Revenue build) | C47: ='Revenue build'!C38 | D47: ='Revenue build'!D38 | E47: ='Revenue build'!E38 | F47: ='Revenue build'!F38 | G47: ='Revenue build'!G38 | H47: ='Revenue build'!H38 | I47: ='Revenue build'!I38 | J47: ='Revenue build'!J38 | ... Q47: ='Revenue build'!Q38
...

Sheet Revenue build
A1: Revenue build: property tax and new growth
A2: How the levy grows: last year's levy limit plus 2.5%, plus new growth, plus any override. New growth comes in five kinds, each a share of last year's levy limit, set on Assumptions and moved by the New growth setting. For FY2026 to FY2031 the forecast starts from the Town's own plan and adds the difference its new growth makes over the Town's flat $2.5M; from FY2032 it carries the levy forward itself. Debt exclusions are shown but set aside on the Forecast sheet.
C4: 2026 | D4: 2027 | E4: 2028 | F4: 2029 | G4: 2030 | H4: 2031 | I4: 2032 | J4: 2033 | K4: 2034 | L4: 2035 | M4: 2036 | N4: 2037 | O4: 2038 | P4: 2039 | Q4: 2040
A6: New growth rates, share of last year's levy limit | C6: This run | D6: Recent trend
A7: New homes | C7: =(IF(OR(GrowthStep<=0,MixCode="mix"),K_ResNewPct*GrowthRate/K_TrendRate,K_ResNewPct+(GrowthRate-K_TrendRate)*IF(MixCode="housing",1,IF(MixCode="even",0.5,0))))*HomesShare | D7: =K_ResNewPct
A8: Home renovation | C8: =IF(OR(GrowthStep<=0,MixCode="mix"),K_ResRenoPct*GrowthRate/K_TrendRate,K_ResRenoPct) | D8: =K_ResRenoPct
A9: New commercial space | C9: =IF(OR(GrowthStep<=0,MixCode="mix"),K_ComNewPct*GrowthRate/K_TrendRate,K_ComNewPct+(GrowthRate-K_TrendRate)*IF(MixCode="commercial",1,IF(MixCode="even",0.5,0))) | D9: =K_ComNewPct
A10: Commercial renovation | C10: =IF(OR(GrowthStep<=0,MixCode="mix"),K_ComRenoPct*GrowthRate/K_TrendRate,K_ComRenoPct) | D10: =K_ComRenoPct
A11: Business equipment | C11: =IF(OR(GrowthStep<=0,MixCode="mix"),K_PP*GrowthRate/K_TrendRate,K_PP) | D11: =K_PP
A12: All new growth | C12: =SUM(C7:C11) | D12: =SUM(D7:D11)
A13: Below the trend every kind is scaled down together. Above it, today's mix scales every kind up; the other mixes add the extra to new homes, new commercial space, or half to each.
A16: The levy, FY2026 to FY2031: the Town's plan plus the difference
A17: Town plan: property tax less debt exclusions, before the May 2026 override | C17: =Data!C5-Data!C6 | D17: =Data!D5-Data!D6 | E17: =Data!E5-Data!E6 | F17: =Data!F5-Data!F6 | G17: =Data!G5-Data!G6 | H17: =Data!H5-Data!H6
A18: May 2026 override, built up (each year's amount, then 2.5% a year) | C18: =N(Data!C8) | D18: =C18*(1+K_LevyCap)+N(Data!D8) | E18: =D18*(1+K_LevyCap)+N(Data!E8) | F18: =E18*(1+K_LevyCap)+N(Data!F8) | G18: =F18*(1+K_LevyCap)+N(Data!G8) | H18: =G18*(1+K_LevyCap)+N(Data!H8)
A19: Town plan levy limit with the override | C19: =C17+C18 | D19: =D17+D18 | E19: =E17+E18 | F19: =F17+F18 | G19: =G17+G18 | H19: =H17+H18
A21: New growth this year
A22: Last year's levy limit (this forecast's: the Town plan's plus the difference, through FY2031) | C22: =Levy2025 | D22: =C36 | E22: =D36 | F22: =E36 | G22: =F36 | H22: =G36 | I22: =H36 | J22: =I36 | K22: =J36 | ... Q22: =P36
A23: Scale to the Town's budgeted new growth (FY2027 only) | C23: =1 | D23: =K_TownNG/((Rate_ResNew+Rate_ResReno+Rate_ComNew+Rate_ComReno+Rate_PP)*D22) | E23: =1 | F23: =1 | G23: =1 | H23: =1 | I23: =1 | J23: =1 | K23: =1 | L23: =1 | ... Q23: =1
A24: New homes | C24: =Rate_ResNew*C22*C23 | D24: =Rate_ResNew*D22*D23 | E24: =Rate_ResNew*E22*E23 | F24: =Rate_ResNew*F22*F23 | G24: =Rate_ResNew*G22*G23 | H24: =Rate_ResNew*H22*H23 | I24: =Rate_ResNew*I22*I23 | J24: =Rate_ResNew*J22*J23 | ... Q24: =Rate_ResNew*Q22*Q23
A25: Home renovation | C25: =Rate_ResReno*C22*C23 | D25: =Rate_ResReno*D22*D23 | E25: =Rate_ResReno*E22*E23 | F25: =Rate_ResReno*F22*F23 | G25: =Rate_ResReno*G22*G23 | H25: =Rate_ResReno*H22*H23 | I25: =Rate_ResReno*I22*I23 | J25: =Rate_ResReno*J22*J23 | ... Q25: =Rate_ResReno*Q22*Q23
A26: New commercial space | C26: =Rate_ComNew*C22*C23 | D26: =Rate_ComNew*D22*D23 | E26: =Rate_ComNew*E22*E23 | F26: =Rate_ComNew*F22*F23 | G26: =Rate_ComNew*G22*G23 | H26: =Rate_ComNew*H22*H23 | I26: =Rate_ComNew*I22*I23 | J26: =Rate_ComNew*J22*J23 | ... Q26: =Rate_ComNew*Q22*Q23
A27: Commercial renovation | C27: =Rate_ComReno*C22*C23 | D27: =Rate_ComReno*D22*D23 | E27: =Rate_ComReno*E22*E23 | F27: =Rate_ComReno*F22*F23 | G27: =Rate_ComReno*G22*G23 | H27: =Rate_ComReno*H22*H23 | I27: =Rate_ComReno*I22*I23 | J27: =Rate_ComReno*J22*J23 | ... Q27: =Rate_ComReno*Q22*Q23
A28: Business equipment | C28: =Rate_PP*C22*C23 | D28: =Rate_PP*D22*D23 | E28: =Rate_PP*E22*E23 | F28: =Rate_PP*F22*F23 | G28: =Rate_PP*G22*G23 | H28: =Rate_PP*H22*H23 | I28: =Rate_PP*I22*I23 | J28: =Rate_PP*J22*J23 | ... Q28: =Rate_PP*Q22*Q23
A29: Chestnut Hill: share built and on the roll | C29: =IF(C$4<K_ChcaStart,0,MIN((C$4-K_ChcaStart+1)/K_ChcaSpan,1)) | D29: =IF(D$4<K_ChcaStart,0,MIN((D$4-K_ChcaStart+1)/K_ChcaSpan,1)) | E29: =IF(E$4<K_ChcaStart,0,MIN((E$4-K_ChcaStart+1)/K_ChcaSpan,1)) | F29: =IF(F$4<K_ChcaStart,0,MIN((F$4-K_ChcaStart+1)/K_ChcaSpan,1)) | G29: =IF(G$4<K_ChcaStart,0,MIN((G$4-K_ChcaStart+1)/K_ChcaSpan,1)) | H29: =IF(H$4<K_ChcaStart,0,MIN((H$4-K_ChcaStart+1)/K_ChcaSpan,1)) | I29: =IF(I$4<K_ChcaStart,0,MIN((I$4-K_ChcaStart+1)/K_ChcaSpan,1)) | J29: =IF(J$4<K_ChcaStart,0,MIN((J$4-K_ChcaStart+1)/K_ChcaSpan,1)) | ... Q29: =IF(Q$4<K_ChcaStart,0,MIN((Q$4-K_ChcaStart+1)/K_ChcaSpan,1))
A30: Chestnut Hill: property tax once on the roll | C30: =C31 | D30: =C30*(1+K_LevyCap)+D31 | E30: =D30*(1+K_LevyCap)+E31 | F30: =E30*(1+K_LevyCap)+F31 | G30: =F30*(1+K_LevyCap)+G31 | H30: =G30*(1+K_LevyCap)+H31 | I30: =H30*(1+K_LevyCap)+I31 | J30: =I30*(1+K_LevyCap)+J31 | K30: =J30*(1+K_LevyCap)+K31 | ... Q30: =P30*(1+K_LevyCap)+Q31
A31: Chestnut Hill: added this year, at its entry year's value | C31: =C29*ChcaProp*(ChcaResShare*((1+K_ResApp)*(1+K_LevyGrowth)/(1+K_BlendApp))^(C$4-K_ChcaDollarYr)+(1-ChcaResShare)*((1+K_ComApp)*(1+K_LevyGrowth)/(1+K_BlendApp))^(C$4-K_ChcaDollarYr)) | D31: =(D29-C29)*ChcaProp*(ChcaResShare*((1+K_ResApp)*(1+K_LevyGrowth)/(1+K_BlendApp))^(D$4-K_ChcaDollarYr)+(1-ChcaResShare)*((1+K_ComApp)*(1+K_LevyGrowth)/(1+K_BlendApp))^(D$4-K_ChcaDollarYr)) | E31: =(E29-D29)*ChcaProp*(ChcaResShare*((1+K_ResApp)*(1+K_LevyGrowth)/(1+K_BlendApp))^(E$4-K_ChcaDollarYr)+(1-ChcaResShare)*((1+K_ComApp)*(1+K_LevyGrowth)/(1+K_BlendApp))^(E$4-K_ChcaDollarYr)) | F31: =(F29-E29)*ChcaProp*(ChcaResShare*((1+K_ResApp)*(1+K_LevyGrowth)/(1+K_BlendApp))^(F$4-K_ChcaDollarYr)+(1-ChcaResShare)*((1+K_ComApp)*(1+K_LevyGrowth)/(1+K_BlendApp))^(F$4-K_ChcaDollarYr)) | G31: =(G29-F29)*ChcaProp*(ChcaResShare*((1+K_ResApp)*(1+K_LevyGrowth)/(1+K_BlendApp))^(G$4-K_ChcaDollarYr)+(1-ChcaResShare)*((1+K_ComApp)*(1+K_LevyGrowth)/(1+K_BlendApp))^(G$4-K_ChcaDollarYr)) | H31: =(H29-G29)*ChcaProp*(ChcaResShare*((1+K_ResApp)*(1+K_LevyGrowth)/(1+K_BlendApp))^(H$4-K_ChcaDollarYr)+(1-ChcaResShare)*((1+K_ComApp)*(1+K_LevyGrowth)/(1+K_BlendApp))^(H$4-K_ChcaDollarYr)) | I31: =(I29-H29)*ChcaProp*(ChcaResShare*((1+K_ResApp)*(1+K_LevyGrowth)/(1+K_BlendApp))^(I$4-K_ChcaDollarYr)+(1-ChcaResShare)*((1+K_ComApp)*(1+K_LevyGrowth)/(1+K_BlendApp))^(I$4-K_ChcaDollarYr)) | J31: =(J29-I29)*ChcaProp*(ChcaResShare*((1+K_ResApp)*(1+K_LevyGrowth)/(1+K_BlendApp))^(J$4-K_ChcaDollarYr)+(1-ChcaResShare)*((1+K_ComApp)*(1+K_LevyGrowth)/(1+K_BlendApp))^(J$4-K_ChcaDollarYr)) | K31: =(K29-J29)*ChcaProp*(ChcaResShare*((1+K_ResApp)*(1+K_LevyGrowth)/(1+K_BlendApp))^(K$4-K_ChcaDollarYr)+(1-ChcaResShare)*((1+K_ComApp)*(1+K_LevyGrowth)/(1+K_BlendApp))^(K$4-K_ChcaDollarYr)) | ... Q31: =(Q29-P29)*ChcaProp*(ChcaResShare*((1+K_ResApp)*(1+K_LevyGrowth)/(1+K_BlendApp))^(Q$4-K_ChcaDollarYr)+(1-ChcaResShare)*((1+K_ComApp)*(1+K_LevyGrowth)/(1+K_BlendApp))^(Q$4-K_ChcaDollarYr))
A32: New growth, all | C32: =SUM(C24:C28)+C31 | D32: =IF(NgEarlyYears="trend",SUM(D24:D28)+D31,IF(NgEarlyYears="permits",K_Perm27,IF(NgEarlyYears="permits_low",K_Perm27Lo,K_Perm27Hi))+D28+D31) | E32: =IF(NgEarlyYears="trend",SUM(E24:E28)+E31,IF(NgEarlyYears="permits",K_Perm28,IF(NgEarlyYears="permits_low",K_Perm28Lo,K_Perm28Hi))+E28+E31) | F32: =SUM(F24:F28)+F31 | G32: =SUM(G24:G28)+G31 | H32: =SUM(H24:H28)+H31 | I32: =SUM(I24:I28)+I31 | J32: =SUM(J24:J28)+J31 | K32: =SUM(K24:K28)+K31 | L32: =SUM(L24:L28)+L31 | M32: =SUM(M24:M28)+M31 | ... Q32: =SUM(Q24:Q28)+Q31
A34: Property tax
A35: Difference from the Town plan's $2.5M a year, carried at 2.5% (FY2027 to FY2031; FY2026 is certified in both) | C35: =0 | D35: =C35*(1+K_LevyCap)+(D32-K_TownNG) | E35: =D35*(1+K_LevyCap)+(E32-K_TownNG) | F35: =E35*(1+K_LevyCap)+(F32-K_TownNG) | G35: =F35*(1+K_LevyCap)+(G32-K_TownNG) | H35: =G35*(1+K_LevyCap)+(H32-K_TownNG)
A36: Levy limit: Town plan plus the difference to FY2031, then last year plus 2.5% plus new growth | C36: =C19+C35 | D36: =D19+D35 | E36: =E19+E35 | F36: =F19+F35 | G36: =G19+G35 | H36: =H19+H35 | I36: =H36*(1+K_LevyCap)+I32 | J36: =I36*(1+K_LevyCap)+J32 | K36: =J36*(1+K_LevyCap)+K32 | L36: =K36*(1+K_LevyCap)+L32 | M36: =L36*(1+K_LevyCap)+M32 | N36: =M36*(1+K_LevyCap)+N32 | O36: =N36*(1+K_LevyCap)+O32 | P36: =O36*(1+K_LevyCap)+P32 | Q36: =P36*(1+K_LevyCap)+Q32
A37: Debt exclusion tax (Town plan, then held at FY2031) | C37: =Data!C6 | D37: =Data!D6 | E37: =Data!E6 | F37: =Data!F6 | G37: =Data!G6 | H37: =Data!H6 | I37: =Data!$H$6 | J37: =Data!$H$6 | K37: =Data!$H$6 | L37: =Data!$H$6 | M37: =Data!$H$6 | N37: =Data!$H$6 | O37: =Data!$H$6 | P37: =Data!$H$6 | Q37: =Data!$H$6
A38: Property tax, all | C38: =C36+C37 | D38: =D36+D37 | E38: =E36+E37 | F38: =F36+F37 | G38: =G36+G37 | H38: =H36+H37 | I38: =I36+I37 | J38: =J36+J37 | ... Q38: =Q36+Q37
A40: Homes and commercial space the new growth stands for
A41: Assessed value of a new home | C41: =K_ResValUnit*(1+K_ResApp)^(C$4-2026) | D41: =K_ResValUnit*(1+K_ResApp)^(D$4-2026) | E41: =K_ResValUnit*(1+K_ResApp)^(E$4-2026) | F41: =K_ResValUnit*(1+K_ResApp)^(F$4-2026) | G41: =K_ResValUnit*(1+K_ResApp)^(G$4-2026) | H41: =K_ResValUnit*(1+K_ResApp)^(H$4-2026) | I41: =K_ResValUnit*(1+K_ResApp)^(I$4-2026) | J41: =K_ResValUnit*(1+K_ResApp)^(J$4-2026) | ... Q41: =K_ResValUnit*(1+K_ResApp)^(Q$4-2026)
A42: Residential tax rate | C42: =K_ResTax*((1+K_LevyGrowth)/(1+K_BlendApp))^(C$4-2026) | D42: =K_ResTax*((1+K_LevyGrowth)/(1+K_BlendApp))^(D$4-2026) | E42: =K_ResTax*((1+K_LevyGrowth)/(1+K_BlendApp))^(E$4-2026) | F42: =K_ResTax*((1+K_LevyGrowth)/(1+K_BlendApp))^(F$4-2026) | G42: =K_ResTax*((1+K_LevyGrowth)/(1+K_BlendApp))^(G$4-2026) | H42: =K_ResTax*((1+K_LevyGrowth)/(1+K_BlendApp))^(H$4-2026) | I42: =K_ResTax*((1+K_LevyGrowth)/(1+K_BlendApp))^(I$4-2026) | J42: =K_ResTax*((1+K_LevyGrowth)/(1+K_BlendApp))^(J$4-2026) | ... Q42: =K_ResTax*((1+K_LevyGrowth)/(1+K_BlendApp))^(Q$4-2026)
A43: Commercial tax rate | C43: =K_ComTax*((1+K_LevyGrowth)/(1+K_BlendApp))^(C$4-2026) | D43: =K_ComTax*((1+K_LevyGrowth)/(1+K_BlendApp))^(D$4-2026) | E43: =K_ComTax*((1+K_LevyGrowth)/(1+K_BlendApp))^(E$4-2026) | F43: =K_ComTax*((1+K_LevyGrowth)/(1+K_BlendApp))^(F$4-2026) | G43: =K_ComTax*((1+K_LevyGrowth)/(1+K_BlendApp))^(G$4-2026) | H43: =K_ComTax*((1+K_LevyGrowth)/(1+K_BlendApp))^(H$4-2026) | I43: =K_ComTax*((1+K_LevyGrowth)/(1+K_BlendApp))^(I$4-2026) | J43: =K_ComTax*((1+K_LevyGrowth)/(1+K_BlendApp))^(J$4-2026) | ... Q43: =K_ComTax*((1+K_LevyGrowth)/(1+K_BlendApp))^(Q$4-2026)
A44: Assessed value per commercial square foot | C44: =K_ComValSqft*(1+K_ComApp)^(C$4-2026) | D44: =K_ComValSqft*(1+K_ComApp)^(D$4-2026) | E44: =K_ComValSqft*(1+K_ComApp)^(E$4-2026) | F44: =K_ComValSqft*(1+K_ComApp)^(F$4-2026) | G44: =K_ComValSqft*(1+K_ComApp)^(G$4-2026) | H44: =K_ComValSqft*(1+K_ComApp)^(H$4-2026) | I44: =K_ComValSqft*(1+K_ComApp)^(I$4-2026) | J44: =K_ComValSqft*(1+K_ComApp)^(J$4-2026) | ... Q44: =K_ComValSqft*(1+K_ComApp)^(Q$4-2026)
A45: Homes added this year | C45: =C24/(C41*C42) | D45: =D24/(D41*D42) | E45: =E24/(E41*E42) | F45: =F24/(F41*F42) | G45: =G24/(G41*G42) | H45: =H24/(H41*H42) | I45: =I24/(I41*I42) | J45: =J24/(J41*J42) | ... Q45: =Q24/(Q41*Q42)
A46: Commercial square feet added this year | C46: =C26/(C44*C43) | D46: =D26/(D44*D43) | E46: =E26/(E44*E43) | F46: =F26/(F44*F43) | G46: =G26/(G44*G43) | H46: =H26/(H44*H43) | I46: =I26/(I44*I43) | J46: =J26/(J44*J43) | ... Q46: =Q26/(Q44*Q43)
A47: Real-estate new growth (all but business equipment) | C47: =SUM(C24:C27) | D47: =SUM(D24:D27) | E47: =SUM(E24:E27) | F47: =SUM(F24:F27) | G47: =SUM(G24:G27) | H47: =SUM(H24:H27) | I47: =SUM(I24:I27) | J47: =SUM(J24:J27) | ... Q47: =SUM(Q24:Q27)
...

Sheet Worked example
A1: Worked example: FY2033, step by step
A2: FY2033 is the first full year after the Town's plan ends, so the levy is carried forward by the forecast alone. Each value is a live cell: change a setting and this page follows. The last column says where the same step is done for every year.
A4: Step | B4: Value | C4: How | D4: Where every year is done
A5: Property tax
A6: Levy limit, FY2032 | B6: ='Revenue build'!I36 | C6: Debt exclusions set aside. | D6: Revenue build
A7: Plus 2.5% | B7: =B6*K_LevyCap | C7: Proposition 2½. | D7: Revenue build
A8: Plus new growth: new homes | B8: ='Revenue build'!J24 | C8: ="Rate "&TEXT(Rate_ResNew,"0.000%")&" of last year's levy limit" | D8: Revenue build
A9: Plus new growth: home renovation | B9: ='Revenue build'!J25 | C9: ="Rate "&TEXT(Rate_ResReno,"0.000%") | D9: Revenue build
A10: Plus new growth: new commercial space | B10: ='Revenue build'!J26 | C10: ="Rate "&TEXT(Rate_ComNew,"0.000%") | D10: Revenue build
A11: Plus new growth: commercial renovation | B11: ='Revenue build'!J27 | C11: ="Rate "&TEXT(Rate_ComReno,"0.000%") | D11: Revenue build
A12: Plus new growth: business equipment | B12: ='Revenue build'!J28 | C12: ="Rate "&TEXT(Rate_PP,"0.000%") | D12: Revenue build
A13: Plus Chestnut Hill added this year | B13: ='Revenue build'!J31 | C13: Fully built by FY2034. | D13: Revenue build
A14: Levy limit, FY2033 | B14: =SUM(B6:B13) | D14: Revenue build
A15: Check: same as Revenue build | B15: =B14-'Revenue build'!J36 | C15: Should be 0.
A16: Homes the new-homes growth stands for | B16: =B8/('Revenue build'!J41*'Revenue build'!J42) | C16: ="New homes growth / (value of a new home "&TEXT('Revenue build'!J41,"$#,##0")&" x residential tax rate "&TEXT('Revenue build'!J42,"0.000%")&")" | D16: Revenue build
A17: Revenue
A18: Property tax, debt exclusions set aside | B18: =Forecast!J7 | C18: The levy limit above. | D18: Forecast
A19: State aid | B19: =Forecast!J8 | C19: ="FY2027 state aid grown "&TEXT(StateAidGrowth,"0.00%")&" a year" | D19: Forecast
A20: Local receipts, as budgeted | B20: =Forecast!J9 | C20: ="Receipts not tied to growth, grown "&TEXT(ReceiptsGrowth,"0.00%")&" a year, plus permits and meals tax; budgeted at "&TEXT(R_BudgetRatio,"0%")&" of what is collected" | D20: Forecast
A21: Free cash | B21: =Forecast!J10 | C21: ="The surplus of FY2031 times "&TEXT(R_ApprShare,"0%") | D21: Forecast
A22: Other available funds and any further override | B22: =Forecast!J11+Forecast!J12 | D22: Forecast
A23: Total revenue | B23: =SUM(B18:B22) | D23: Forecast
A24: Spending
A25: Town departments, today's services | B25: =Forecast!J16 | C25: ="FY2027 budget x ("&TEXT(K_pD,"0%")&" pay x pay index "&TEXT(Forecast!J66,"0.000")&" + the rest x price index "&TEXT(Forecast!J58,"0.000")&")" | D25: Forecast
A26: Town services for added homes and businesses | B26: =Forecast!J17 | C26: =TEXT(Forecast!J34,"#,##0")&" homes added since FY2027 at "&TEXT(CostHome,"$#,##0")&" (FY2025 $, less fire's share, which comes as a company), plus any fire company and police steps" | D26: Forecast
A27: Schools | B27: =Forecast!J18 | C27: ="FY2027 budget: pay part x pay index x staff "&TEXT(Forecast!J33,"#,##0")&" / "&TEXT(Staff27,"#,##0")&"; the rest x prices, two thirds moving with enrollment "&TEXT(Forecast!J32,"#,##0") | D27: Forecast
A28: Health insurance | B28: =Forecast!J19 | C28: ="FY2027 budget x subscribers "&TEXT(Forecast!J71,"0.000")&" x premiums "&TEXT(Forecast!J60,"0.000") | D28: Forecast
A29: Pensions, retiree health, other benefits | B29: =Forecast!J21+Forecast!J22+Forecast!J23+Forecast!J20 | C29: Town schedules to FY2031, then with payroll; benefits for staff added by growth. | D29: Forecast
A30: Debt within the levy; capital, reserves and other | B30: =Forecast!J24+Forecast!J25 | D30: Forecast
A31: Total spending | B31: =SUM(B25:B30) | D31: Forecast
A32: Room: revenue minus spending | B32: =B23-B31 | D32: Forecast
A33: Check: same as Forecast | B33: =B32-Forecast!J29 | C33: Should be 0.

Sheet Assumptions
A1: Assumptions
A2: Every fixed number the forecast uses. Black values are formulas: measured from the History sheet or worked out from published figures, so you can change the years averaged or a source figure and the whole forecast follows. Blue values are typed from the source named. The settings you are meant to vary are on the Settings sheet; these are the numbers underneath them.
A4: Name | B4: Assumption | C4: Value used | D4: How it is worked out | E4: Source
A6: Property tax: the levy limit and new growth
A7: K_LevyCap | B7: Yearly increase allowed on the levy limit | C7: 0.025 | D7: Proposition 2½: the levy limit rises 2.5% a year, plus new growth and any override. | E7: Massachusetts General Laws c.59 §21C
A8: K_ResTrail | B8: Residential new growth, share of the prior year's levy limit | C8: =ROUND(AVERAGE(History!$S$22:$S$26),5) | D8: Average of FY2022 to FY2026 on History, rounded to 0.001 point. Change the years to test another window. | E8: DLS new growth (History)
A9: K_ComTrail | B9: Commercial, industrial and business equipment new growth, share of the prior levy limit | C9: =ROUND(AVERAGE(History!$U$22:$U$26),5) | D9: Average of FY2022 to FY2026 on History, rounded the same way. | E9: DLS new growth (History)
A10: K_TrendRate | B10: Recent new growth rate, all property | C10: =K_ResTrail+K_ComTrail | D10: The two together. The New growth setting moves the rate up or down from here in tenths of a point.
A11: K_ResNewShare | B11: Share of residential new growth from net new homes (the rest is renovation) | C11: =ROUND(K_HomesPace*K_ResValUnit*K_ResTax/(K_ResTrail*Levy2025),4) | D11: Set so FY2026 carries the recent pace of net new homes at the value each adds. Total residential new growth stays at its trend rate, which has held at 0.8% to 1.0% of the levy whether few or many homes were built; renovation, including houses rebuilt as houses, is the rest. | E11: Building permits and assessment rolls (new_homes_parameters.py)
A12: K_ComNewShare | B12: Share of commercial new growth from new or converted buildings | C12: =ROUND(AVERAGE(History!$G$46:$G$50),4) | D12: Average of FY2021 to FY2025, same table. Most commercial new growth is renovation and fit-out. | E12: Same
A13: K_PP | B13: Business equipment (personal property) new growth, share of the prior levy limit | C13: 0.002407 | D13: Average of FY2022 to FY2026 on History (=AVERAGE(History!$B$55:$B$59) gives 0.24070%), rounded to 0.2407%. Part of the commercial rate above, not added to it. | E13: Board of Assessors classification hearings
A14: K_ResNewPct | B14: New growth rate from new homes | C14: =K_ResTrail*K_ResNewShare | D14: Residential rate times the new-homes share.
A15: K_ResRenoPct | B15: New growth rate from home renovation | C15: =K_ResTrail*(1-K_ResNewShare) | D15: Residential rate times the rest.
A16: K_ComNewPct | B16: New growth rate from new commercial space | C16: =K_ComTrail*K_ComNewShare | D16: Commercial rate times the new-buildings share.
A17: K_ComRenoPct | B17: New growth rate from commercial renovation | C17: =K_ComTrail-K_ComNewPct-K_PP | D17: What is left of the commercial rate after new buildings and equipment.
A18: K_TownNG | B18: New growth in the Town's own plan, each year | C18: 2500000 | D18: The Town's long-range plan assumes a flat $2.5M. For FY2026 to FY2031 the forecast starts from the Town's own property tax figures and adds only the difference its new growth makes; see Revenue build. | E18: Town long-range plan, Jan 2026
A19: K_Perm27 | B19: FY2027 real estate new growth tax the 2024 permits point to, middle of past rates | C19: 1946151 | D19: Taxable permits times the middle of past ratios of new growth to permits, at the FY2026 tax rate. | E19: Town permit records; DLS new growth (permit_leading_indicator.py)
A20: K_Perm27Lo | B20: The same, low end of past rates | C20: 1783406 | E20: Same
A21: K_Perm27Hi | B21: The same, high end of past rates | C21: 2454037 | E21: Same
A22: K_Perm28 | B22: FY2028 real estate new growth tax the 2025 permits point to, middle of past rates | C22: 2037866 | D22: As above. FY2028 is taxed at the FY2027 rate, a little higher after the override, so this runs about 3% low. | E22: Same
A23: K_Perm28Lo | B23: The same, low end of past rates | C23: 1867452 | E23: Same
A24: K_Perm28Hi | B24: The same, high end of past rates | C24: 2569687 | E24: Same
A25: K_NG2026 | B25: New growth in FY2026, as certified | C25: =History!$D$26 | D25: FY2026 is past, so every run uses the certified figure; the rates above apply from FY2027. | E25: DLS new growth (History)
A26: Levy2025 | B26: FY2025 levy, debt exclusions set aside | C26: =History!$G$25-History!$F$25 | D26: Total levy raised less debt exclusion tax. New growth in FY2026 is measured against it. | E26: History
A28: Turning new growth dollars into homes and commercial space
A29: K_HomesPace | B29: Net new homes a year, building permits issued 2016 to 2025 | C29: 104.7 | D29: Every permit read and coded by hand, net of demolitions, assisted living counted separately. | E29: Town building permits (output/permit_homes_by_year.csv)
A30: K_ResValUnit | B30: Assessed value added by one net new home, FY2026 | C30: 585000 | D30: The forecast adds apartments and condominiums, in their 2016 to 2025 proportions (about 80 to 20): apartments add about $521,000 of assessed value per net home and small multifamily and condominium buildings about $864,000, measured on the new-growth basis. | E30: Building permits followed onto the assessment rolls, FY2016 to FY2026
A31: K_ResApp | B31: Yearly rise in the value of a new home | C31: 0.0496 | D31: Town-wide residential value growth net of new growth, FY2018 to FY2024 average. | E31: Assessment rolls
A32: K_ComValSqft | B32: Assessed value per square foot of new commercial space, FY2026 | C32: 518 | D32: Taxable commercial value divided by commercial floor area, weighted (median $529). | E32: Assessment rolls
A33: K_ComApp | B33: Yearly rise in commercial value per square foot | C33: 0.0128 | D33: Town-wide commercial value growth net of new growth, FY2018 to FY2024; volatile in 2020 to 2023. | E33: Assessment rolls
A34: K_ResTax | B34: Residential tax rate, FY2026 (per dollar of value) | C34: 0.009836 | D34: $9.836 per $1,000. | E34: Board of Assessors, FY2026 classification
A35: K_ComTax | B35: Commercial tax rate, FY2026 (per dollar of value) | C35: 0.016238 | D35: $16.238 per $1,000. | E35: Board of Assessors, FY2026 classification
A36: K_ResValShare | B36: Residential share of taxable value, FY2026 | C36: =30758464684/33832309213 | D36: Residential value over all taxable value. | E36: Board of Assessors, FY2026 classification
A37: K_LevyGrowth | B37: Yearly levy growth at the recent pace | C37: =K_LevyCap+K_ResTrail+K_ComTrail | D37: 2.5% plus recent new growth.
A38: K_BlendApp | B38: Yearly rise in taxable value, all property | C38: =K_ResValShare*K_ResApp+(1-K_ResValShare)*K_ComApp | D38: The two value growth rates weighted by value. Tax rates drift by the levy's growth over this.
A40: Local receipts and state aid
A41: K_PermitRate26 | B41: Building permit fee, through FY2026 (share of construction cost) | C41: 0.02 | D41: $20 per $1,000 of estimated cost. | E41: Town fee schedule, 2022
A42: K_PermitRate27 | B42: Building permit fee, from FY2027 | C42: 0.021 | D42: $21 per $1,000, effective July 1, 2026. | E42: Town fee schedule, 2026
A43: K_Permits2025 | B43: Building permit revenue, FY2025 | C43: 4439224 | E43: DLS local receipts, FY2025
A44: K_Inv2019 | B44: Investment income, FY2019 | C44: 1317178 | E44: DLS local receipts
...

Sheet History
A1: History, FY2005 to FY2025
A2: The record the assumptions are measured from (FY2026: new growth only, as certified). Levy, new growth and overrides: Massachusetts Division of Local Services (DLS) levy limit and new growth reports. Revenue and spending: DLS Schedule A. State aid and local receipts: DLS recap sheets and Local Receipts Actual vs Estimate. Surplus: DLS certified free cash. Grey columns are worked out here.
A4: Fiscal year | B4: Levy limit, prior year | C4: 2.5% increase | D4: New growth applied to the levy | E4: Override | F4: Debt exclusions | G4: Total levy raised | H4: Residential new growth applied | I4: State aid | J4: Local receipts, budget estimate | K4: Local receipts, actual | L4: General Fund surplus (certified free cash basis) | M4: Total revenues, Schedule A | N4: Spending: General Government | O4: Spending: Public Safety | P4: Spending: Public Works | Q4: Spending: Human Services | R4: Spending: Culture and Recreation | S4: Residential new growth, share of prior levy limit | T4: All new growth, share of prior levy limit | U4: Commercial, industrial and business equipment new growth, share | V4: Surplus not from receipts beating budget, share of revenue
A5: 2005 | B5: 112976154 | C5: 2824404 | D5: 2386251 | E5: 0 | F5: 1676384 | G5: 119852046 | H5: 1744877 | I5: 17094030 | L5: -1032557 | M5: 167934717 | N5: 12211085 | O5: 25373371 | P5: 13742331 | Q5: 1652626 | R5: 6481806 | S5: =IFERROR(H5/B5,"") | T5: =IFERROR(D5/B5,"") | U5: =IFERROR(T5-S5,"") | V5: =IFERROR((L5-(K5-J5))/M5,"")
A6: 2006 | B6: 118188364 | C6: 2954709 | D6: 2232945 | E6: 0 | F6: 1648735 | G6: 125014839 | H6: 1621827 | I6: 18027706 | L6: -1357404 | M6: 168890619 | N6: 10787649 | O6: 26195248 | P6: 13221815 | Q6: 1765849 | R6: 7220217 | S6: =IFERROR(H6/B6,"") | T6: =IFERROR(D6/B6,"") | U6: =IFERROR(T6-S6,"") | V6: =IFERROR((L6-(K6-J6))/M6,"")
A7: 2007 | B7: 123389202 | C7: 3084730 | D7: 1989683 | E7: 0 | F7: 1614854 | G7: 130076534 | H7: 1241582 | I7: 18021104 | L7: -142494 | M7: 178383652 | N7: 12219549 | O7: 27115817 | P7: 12908584 | Q7: 1838460 | R7: 7020520 | S7: =IFERROR(H7/B7,"") | T7: =IFERROR(D7/B7,"") | U7: =IFERROR(T7-S7,"") | V7: =IFERROR((L7-(K7-J7))/M7,"")
A8: 2008 | B8: 128463616 | C8: 3211590 | D8: 2584680 | E8: 0 | F8: 1568947 | G8: 135811901 | H8: 2157624 | I8: 18973131 | L8: -913423 | M8: 185803513 | N8: 11203008 | O8: 26915155 | P8: 12454642 | Q8: 1819321 | R8: 7264628 | S8: =IFERROR(H8/B8,"") | T8: =IFERROR(D8/B8,"") | U8: =IFERROR(T8-S8,"") | V8: =IFERROR((L8-(K8-J8))/M8,"")
A9: 2009 | B9: 134259886 | C9: 3356497 | D9: 1828261 | E9: 6200000 | F9: 1692697 | G9: 147273068 | H9: 1306004 | I9: 19623724 | L9: 1826552 | M9: 192482479 | N9: 12366076 | O9: 28141128 | P9: 13670118 | Q9: 1950819 | R9: 6951910 | S9: =IFERROR(H9/B9,"") | T9: =IFERROR(D9/B9,"") | U9: =IFERROR(T9-S9,"") | V9: =IFERROR((L9-(K9-J9))/M9,"")
A10: 2010 | B10: 145644644 | C10: 3641116 | D10: 1762212 | E10: 0 | F10: 1667074 | G10: 152681998 | H10: 1474371 | I10: 16536492 | L10: 8812147 | M10: 195166931 | N10: 9531358 | O10: 27080345 | P10: 10509904 | Q10: 1840552 | R10: 5961909 | S10: =IFERROR(H10/B10,"") | T10: =IFERROR(D10/B10,"") | U10: =IFERROR(T10-S10,"") | V10: =IFERROR((L10-(K10-J10))/M10,"")
A11: 2011 | B11: 151047972 | C11: 3776199 | D11: 1829084 | E11: 0 | F11: 1258944 | G11: 157878286 | H11: 1382518 | I11: 13796542 | L11: 10153141 | M11: 197401346 | N11: 9347954 | O11: 28030700 | P11: 11997166 | Q11: 1992869 | R11: 5863962 | S11: =IFERROR(H11/B11,"") | T11: =IFERROR(D11/B11,"") | U11: =IFERROR(T11-S11,"") | V11: =IFERROR((L11-(K11-J11))/M11,"")
A12: 2012 | B12: 156653255 | C12: 3916331 | D12: 1984224 | E12: 0 | F12: 1090408 | G12: 163620490 | H12: 1565148 | I12: 13383563 | L12: -890993 | M12: 212032653 | N12: 9589942 | O12: 28551429 | P12: 10630118 | Q12: 1973567 | R12: 6151817 | S12: =IFERROR(H12/B12,"") | T12: =IFERROR(D12/B12,"") | U12: =IFERROR(T12-S12,"") | V12: =IFERROR((L12-(K12-J12))/M12,"")
A13: 2013 | B13: 162553810 | C13: 4063845 | D13: 1920101 | E13: 0 | F13: 1630808 | G13: 170137612 | H13: 1578310 | I13: 15131276 | L13: 13901701 | M13: 225013338 | N13: 9818063 | O13: 28793603 | P13: 11529565 | Q13: 2101592 | R13: 6679258 | S13: =IFERROR(H13/B13,"") | T13: =IFERROR(D13/B13,"") | U13: =IFERROR(T13-S13,"") | V13: =IFERROR((L13-(K13-J13))/M13,"")
A14: 2014 | B14: 168537757 | C14: 4213444 | D14: 1935408 | E14: 0 | F14: 1112800 | G14: 175783902 | H14: 1368618 | I14: 16659162 | L14: 10338640 | M14: 223722368 | N14: 10106970 | O14: 29099113 | P14: 12148636 | Q14: 2045258 | R14: 6816841 | S14: =IFERROR(H14/B14,"") | T14: =IFERROR(D14/B14,"") | U14: =IFERROR(T14-S14,"") | V14: =IFERROR((L14-(K14-J14))/M14,"")
A15: 2015 | B15: 174686609 | C15: 4367165 | D15: 2100566 | E15: 0 | F15: 1094400 | G15: 182239297 | H15: 1435526 | I15: 17634875 | L15: 9687851 | M15: 231276828 | N15: 10437557 | O15: 30219418 | P15: 13519758 | Q15: 2138615 | R15: 6868458 | S15: =IFERROR(H15/B15,"") | T15: =IFERROR(D15/B15,"") | U15: =IFERROR(T15-S15,"") | V15: =IFERROR((L15-(K15-J15))/M15,"")
A16: 2016 | B16: 181154340 | C16: 4528858 | D16: 2090726 | E16: 7665000 | F16: 1076000 | G16: 195049924 | H16: 1568178 | I16: 18837306 | L16: 15546838 | M16: 249427185 | N16: 10864873 | O16: 30701920 | P16: 11878933 | Q16: 2185490 | R16: 7014558 | S16: =IFERROR(H16/B16,"") | T16: =IFERROR(D16/B16,"") | U16: =IFERROR(T16-S16,"") | V16: =IFERROR((L16-(K16-J16))/M16,"")
A17: 2017 | B17: 195438924 | C17: 4885973 | D17: 2711620 | E17: 0 | F17: 1048400 | G17: 204064199 | H17: 1842898 | I17: 19657251 | J17: 24212598 | K17: 29013746 | L17: 13613951 | M17: 259094788 | N17: 11619881 | O17: 32523188 | P17: 12311822 | Q17: 2202722 | R17: 7165225 | S17: =IFERROR(H17/B17,"") | T17: =IFERROR(D17/B17,"") | U17: =IFERROR(T17-S17,"") | V17: =IFERROR((L17-(K17-J17))/M17,"")
A18: 2018 | B18: 203036517 | C18: 5075913 | D18: 2264107 | E18: 0 | F18: 1020800 | G18: 211374488 | H18: 1646231 | I18: 20352973 | J18: 29836380 | K18: 36696432 | L18: 12688465 | M18: 269899635 | N18: 11723637 | O18: 32252448 | P18: 13330596 | Q18: 2163588 | R18: 7234336 | S18: =IFERROR(H18/B18,"") | T18: =IFERROR(D18/B18,"") | U18: =IFERROR(T18-S18,"") | V18: =IFERROR((L18-(K18-J18))/M18,"")
A19: 2019 | B19: 210376535 | C19: 5259413 | D19: 2601328 | E19: 6575425 | F19: 3408089 | G19: 224490569 | H19: 1617248 | I19: 22112765 | J19: 30055136 | K19: 36314826 | L19: 14992579 | M19: 285287238 | N19: 12444751 | O19: 34584040 | P19: 13321964 | Q19: 2318926 | R19: 7353301 | S19: =IFERROR(H19/B19,"") | T19: =IFERROR(D19/B19,"") | U19: =IFERROR(T19-S19,"") | V19: =IFERROR((L19-(K19-J19))/M19,"")
